<?xml version="1.0" ?>
<!-- =================================================================================== -->
<!-- |    This document was autogenerated by xacro from moveo.urdf.xacro               | -->
<!-- |    EDITING THIS FILE BY HAND IS NOT RECOMMENDED                                 | -->
<!-- =================================================================================== -->
<!--
  Robot model adapted from
https://github.com/CIR-KIT/steer_drive_ros/blob/kinetic-devel/steer_drive_controller/test/common/urdf/steerbot.xacro

  Modifications:
    Remove base_footprint link. Useful for navigation but not necessary for a simple example.
    Added materials for URDF
    Updated inertials

  Geometry:
    The Ackermann steering controllers require the longitudinal
    separation between the front and back wheel axes and the
    lateral separation between the left and right front steering axes.
    
    For this model:
    wheel_separation_h = base_length - 2 * axle_offset = 0. 4
    wheel_separation_w = base_width  + 2 * steer_offset = 0.4
-->
<robot name="mobile_base">
  <material name="red">
    <color rgba="0.8 0 0 1"/>
  </material>
  <material name="green">
    <color rgba="0 0.8 0 1"/>
  </material>
  <material name="blue">
    <color rgba="0 0 0.8 1"/>
  </material>
  <material name="yellow">
    <color rgba="0.8 0.8 0 1"/>
  </material>
  <material name="orange">
    <color rgba="0.8 0.25 0 1"/>
  </material>
  <material name="black">
    <color rgba="0 0 0 1"/>
  </material>
  <material name="dark_gray">
    <color rgba="0.5 0.5 0.5 1"/>
  </material>
  <material name="gray">
    <color rgba="0.753 0.753 0.753 1"/>
  </material>
  <material name="silver">
    <color rgba="0.88 0.88 0.88 1"/>
  </material>
  <material name="white">
    <color rgba="1 1 1 1"/>
  </material>
  <!-- Gazebo plugins
    <gazebo> -->
  <!-- Load ros_control plugin using the steer_bot_hardware_gazebo
        implementation of the hardware_interface::RobotHW -->
  <!-- <plugin name="gazebo_ros_control" filename="libgazebo_ros_control.so">
        <robotNamespace>${namespace}</robotNamespace>
        <robotSimType>steer_bot_hardware_gazebo/SteerBotHardwareGazebo</robotSimType>
        <legacyModeNS>false</legacyModeNS>
        </plugin> -->
  <!-- </gazebo> -->
  <!-- <gazebo>
        <plugin filename="ign_ros2_control-system"
            name="ign_ros2_control::IgnitionROS2ControlPlugin">
            <parameters>$(find sam_bot_nav2_gz)/config/diff_drive_controller_velocity.yaml</parameters>
        </plugin>
    </gazebo> -->
  <!-- Base link -->
  <link name="base_link">
    <visual>
      <origin rpy="3.14 0 0" xyz="-0.275 0 0"/>
      <geometry>
        <mesh filename="package://mobile_base/urdf/base/meshes/moveo_body.dae"/>
      </geometry>
    </visual>
    <collision>
      <origin rpy="0 0 0" xyz="0 0 0"/>
      <geometry>
        <box size="0.7 0.47 0.1"/>
      </geometry>
    </collision>
    <inertial>
      <origin rpy="0 0 0" xyz="0 0 0"/>
      <mass value="5"/>
      <inertia ixx="0.09620833333333334" ixy="0.0" ixz="0.0" iyy="0.2083333333333333" iyz="0.0" izz="0.29620833333333324"/>
    </inertial>
  </link>
  <!-- Base pole -->
  <joint name="base_pole_joint" type="fixed">
    <origin rpy="0 0 0" xyz="0 0 1.3"/>
    <parent link="base_link"/>
    <child link="base_pole"/>
  </joint>
  <link name="base_pole">
    <visual>
      <origin rpy="0.0 0 0" xyz="0.0 0 0"/>
      <geometry>
        <cylinder length="1.4" radius="0.04"/>
      </geometry>
    </visual>
    <collision>
      <origin rpy="0 0 0" xyz="0 0 0"/>
      <geometry>
        <cylinder length="1.5" radius="0.04"/>
      </geometry>
    </collision>
  </link>
  <link name="front_steer_link">
    <visual>
      <origin rpy="0 0 0" xyz="0 0 0"/>
      <geometry>
        <cylinder length="0.02" radius="0.05"/>
      </geometry>
      <material name="yellow"/>
    </visual>
    <collision>
      <origin rpy="0 0 0" xyz="0 0 0"/>
      <geometry>
        <cylinder length="0.02" radius="0.05"/>
      </geometry>
    </collision>
    <inertial>
      <origin rpy="0 0 0" xyz="0 0 0"/>
      <mass value="1"/>
      <inertia ixx="0.0006583333333333334" ixy="0.0" ixz="0.0" iyy="0.0006583333333333334" iyz="0.0" izz="0.0012500000000000002"/>
    </inertial>
  </link>
  <joint name="front_steer_joint" type="revolute">
    <parent link="base_link"/>
    <child link="front_steer_link"/>
    <origin rpy="0 0 0" xyz="0.27499999999999997 0 0.12000000000000001"/>
    <axis xyz="0 0 1"/>
    <limit effort="10.0" lower="-3.141592653589793" upper="3.141592653589793" velocity="5.0"/>
  </joint>
  <transmission name="front_steer_joint_trans">
    <type>transmission_interface/SimpleTransmission</type>
    <actuator name="front_steer_joint_motor">
      <mechanicalReduction>1</mechanicalReduction>
      <hardwareInterface>hardware_interface/PositionJointInterface</hardwareInterface>
    </actuator>
    <joint name="front_steer_joint">
      <hardwareInterface>hardware_interface/PositionJointInterface</hardwareInterface>
    </joint>
  </transmission>
  <gazebo reference="front_steer_link">
    <material>Gazebo/Yellow</material>
  </gazebo>
  <link name="rear_wheel_link">
    <visual>
      <origin rpy="0 0 0" xyz="0 0 0"/>
      <geometry>
        <cylinder length="0.025" radius="0.025"/>
      </geometry>
      <material name="yellow"/>
    </visual>
    <collision>
      <origin rpy="0 0 0" xyz="0 0 0"/>
      <geometry>
        <cylinder length="0.025" radius="0.025"/>
      </geometry>
    </collision>
    <inertial>
      <origin rpy="0 0 0" xyz="0 0 0"/>
      <mass value="0.03125"/>
      <inertia ixx="6.510416666666668e-06" ixy="0.0" ixz="0.0" iyy="6.510416666666668e-06" iyz="0.0" izz="9.765625000000002e-06"/>
    </inertial>
  </link>
  <joint name="rear_wheel_joint" type="continuous">
    <parent link="base_link"/>
    <child link="rear_wheel_link"/>
    <origin rpy="-1.5707963267948966 0 0" xyz="-0.27499999999999997 0 0"/>
    <axis xyz="0 0 1"/>
  </joint>
  <transmission name="rear_wheel_joint_trans">
    <type>transmission_interface/SimpleTransmission</type>
    <actuator name="rear_wheel_joint_motor">
      <mechanicalReduction>1</mechanicalReduction>
      <hardwareInterface>hardware_interface/VelocityJointInterface</hardwareInterface>
    </actuator>
    <joint name="rear_wheel_joint">
      <hardwareInterface>hardware_interface/VelocityJointInterface</hardwareInterface>
    </joint>
  </transmission>
  <gazebo reference="rear_wheel_link">
    <material>Gazebo/Yellow</material>
  </gazebo>
  <link name="front_right_steer_link">
    <visual>
      <origin rpy="0 0 0" xyz="0 0 0"/>
      <geometry>
        <cylinder length="0.02" radius="0.05"/>
      </geometry>
      <material name="blue"/>
    </visual>
    <collision>
      <origin rpy="0 0 0" xyz="0 0 0"/>
      <geometry>
        <cylinder length="0.02" radius="0.05"/>
      </geometry>
    </collision>
    <inertial>
      <origin rpy="0 0 0" xyz="0 0 0"/>
      <mass value="1"/>
      <inertia ixx="0.0006583333333333334" ixy="0.0" ixz="0.0" iyy="0.0006583333333333334" iyz="0.0" izz="0.0012500000000000002"/>
    </inertial>
  </link>
  <joint name="front_right_steer_joint" type="revolute">
    <parent link="base_link"/>
    <child link="front_right_steer_link"/>
    <origin rpy="0 0 0" xyz="0.27499999999999997 -0.31 0.12000000000000001"/>
    <axis xyz="0 0 1"/>
    <limit effort="10.0" lower="-0.7853981633974483" upper="0.7853981633974483" velocity="5.0"/>
  </joint>
  <link name="front_right_wheel_link">
    <visual>
      <origin rpy="0 0 0" xyz="0 0 0"/>
      <geometry>
        <cylinder length="0.05" radius="0.1"/>
      </geometry>
      <material name="red"/>
    </visual>
    <collision>
      <origin rpy="0 0 0" xyz="0 0 0"/>
      <geometry>
        <cylinder length="0.05" radius="0.1"/>
      </geometry>
    </collision>
    <inertial>
      <origin rpy="0 0 0" xyz="0 0 0"/>
      <mass value="1"/>
      <inertia ixx="0.002708333333333334" ixy="0.0" ixz="0.0" iyy="0.002708333333333334" iyz="0.0" izz="0.005000000000000001"/>
    </inertial>
  </link>
  <joint name="front_right_wheel_joint" type="continuous">
    <parent link="front_right_steer_link"/>
    <child link="front_right_wheel_link"/>
    <origin rpy="-1.5707963267948966 0 0" xyz="0 0 -0.12000000000000001"/>
    <axis xyz="0 0 1"/>
  </joint>
  <transmission name="front_right_steer_joint_trans">
    <type>transmission_interface/SimpleTransmission</type>
    <actuator name="front_right_steer_joint_motor">
      <mechanicalReduction>1</mechanicalReduction>
      <hardwareInterface>hardware_interface/PositionJointInterface</hardwareInterface>
    </actuator>
    <joint name="front_right_steer_joint">
      <hardwareInterface>hardware_interface/PositionJointInterface</hardwareInterface>
    </joint>
  </transmission>
  <transmission name="front_right_wheel_joint_trans">
    <type>transmission_interface/SimpleTransmission</type>
    <actuator name="front_right_wheel_joint_motor">
      <mechanicalReduction>1</mechanicalReduction>
      <hardwareInterface>hardware_interface/VelocityJointInterface</hardwareInterface>
    </actuator>
    <joint name="front_right_wheel_joint">
      <hardwareInterface>hardware_interface/VelocityJointInterface</hardwareInterface>
    </joint>
  </transmission>
  <gazebo reference="front_right_steer_link">
    <material>Gazebo/Blue</material>
  </gazebo>
  <gazebo reference="front_right_wheel_link">
    <material>Gazebo/Red</material>
  </gazebo>
  <link name="front_left_steer_link">
    <visual>
      <origin rpy="0 0 0" xyz="0 0 0"/>
      <geometry>
        <cylinder length="0.02" radius="0.05"/>
      </geometry>
      <material name="blue"/>
    </visual>
    <collision>
      <origin rpy="0 0 0" xyz="0 0 0"/>
      <geometry>
        <cylinder length="0.02" radius="0.05"/>
      </geometry>
    </collision>
    <inertial>
      <origin rpy="0 0 0" xyz="0 0 0"/>
      <mass value="1"/>
      <inertia ixx="0.0006583333333333334" ixy="0.0" ixz="0.0" iyy="0.0006583333333333334" iyz="0.0" izz="0.0012500000000000002"/>
    </inertial>
  </link>
  <joint name="front_left_steer_joint" type="revolute">
    <parent link="base_link"/>
    <child link="front_left_steer_link"/>
    <origin rpy="0 0 0" xyz="0.27499999999999997 0.31 0.12000000000000001"/>
    <axis xyz="0 0 1"/>
    <limit effort="10.0" lower="-0.7853981633974483" upper="0.7853981633974483" velocity="5.0"/>
  </joint>
  <link name="front_left_wheel_link">
    <visual>
      <origin rpy="0 0 0" xyz="0 0 0"/>
      <geometry>
        <cylinder length="0.05" radius="0.1"/>
      </geometry>
      <material name="red"/>
    </visual>
    <collision>
      <origin rpy="0 0 0" xyz="0 0 0"/>
      <geometry>
        <cylinder length="0.05" radius="0.1"/>
      </geometry>
    </collision>
    <inertial>
      <origin rpy="0 0 0" xyz="0 0 0"/>
      <mass value="1"/>
      <inertia ixx="0.002708333333333334" ixy="0.0" ixz="0.0" iyy="0.002708333333333334" iyz="0.0" izz="0.005000000000000001"/>
    </inertial>
  </link>
  <joint name="front_left_wheel_joint" type="continuous">
    <parent link="front_left_steer_link"/>
    <child link="front_left_wheel_link"/>
    <origin rpy="-1.5707963267948966 0 0" xyz="0 0 -0.12000000000000001"/>
    <axis xyz="0 0 1"/>
  </joint>
  <transmission name="front_left_steer_joint_trans">
    <type>transmission_interface/SimpleTransmission</type>
    <actuator name="front_left_steer_joint_motor">
      <mechanicalReduction>1</mechanicalReduction>
      <hardwareInterface>hardware_interface/PositionJointInterface</hardwareInterface>
    </actuator>
    <joint name="front_left_steer_joint">
      <hardwareInterface>hardware_interface/PositionJointInterface</hardwareInterface>
    </joint>
  </transmission>
  <transmission name="front_left_wheel_joint_trans">
    <type>transmission_interface/SimpleTransmission</type>
    <actuator name="front_left_wheel_joint_motor">
      <mechanicalReduction>1</mechanicalReduction>
      <hardwareInterface>hardware_interface/VelocityJointInterface</hardwareInterface>
    </actuator>
    <joint name="front_left_wheel_joint">
      <hardwareInterface>hardware_interface/VelocityJointInterface</hardwareInterface>
    </joint>
  </transmission>
  <gazebo reference="front_left_steer_link">
    <material>Gazebo/Blue</material>
  </gazebo>
  <gazebo reference="front_left_wheel_link">
    <material>Gazebo/Red</material>
  </gazebo>
  <link name="rear_right_wheel_link">
    <visual>
      <origin rpy="0 0 0" xyz="0 0 0"/>
      <geometry>
        <cylinder length="0.05" radius="0.1"/>
      </geometry>
      <material name="red"/>
    </visual>
    <collision>
      <origin rpy="0 0 0" xyz="0 0 0"/>
      <geometry>
        <cylinder length="0.05" radius="0.1"/>
      </geometry>
    </collision>
    <inertial>
      <origin rpy="0 0 0" xyz="0 0 0"/>
      <mass value="1"/>
      <inertia ixx="0.002708333333333334" ixy="0.0" ixz="0.0" iyy="0.002708333333333334" iyz="0.0" izz="0.005000000000000001"/>
    </inertial>
  </link>
  <joint name="rear_right_wheel_joint" type="continuous">
    <parent link="base_link"/>
    <child link="rear_right_wheel_link"/>
    <origin rpy="-1.5707963267948966 0 0" xyz="-0.27499999999999997 -0.31 0"/>
    <axis xyz="0 0 1"/>
  </joint>
  <transmission name="rear_right_wheel_joint_trans">
    <type>transmission_interface/SimpleTransmission</type>
    <actuator name="rear_right_wheel_joint_motor">
      <mechanicalReduction>1</mechanicalReduction>
      <hardwareInterface>hardware_interface/VelocityJointInterface</hardwareInterface>
    </actuator>
    <joint name="rear_right_wheel_joint">
      <hardwareInterface>hardware_interface/VelocityJointInterface</hardwareInterface>
    </joint>
  </transmission>
  <gazebo reference="rear_right_wheel_link">
    <material>Gazebo/Red</material>
  </gazebo>
  <link name="rear_left_wheel_link">
    <visual>
      <origin rpy="0 0 0" xyz="0 0 0"/>
      <geometry>
        <cylinder length="0.05" radius="0.1"/>
      </geometry>
      <material name="red"/>
    </visual>
    <collision>
      <origin rpy="0 0 0" xyz="0 0 0"/>
      <geometry>
        <cylinder length="0.05" radius="0.1"/>
      </geometry>
    </collision>
    <inertial>
      <origin rpy="0 0 0" xyz="0 0 0"/>
      <mass value="1"/>
      <inertia ixx="0.002708333333333334" ixy="0.0" ixz="0.0" iyy="0.002708333333333334" iyz="0.0" izz="0.005000000000000001"/>
    </inertial>
  </link>
  <joint name="rear_left_wheel_joint" type="continuous">
    <parent link="base_link"/>
    <child link="rear_left_wheel_link"/>
    <origin rpy="-1.5707963267948966 0 0" xyz="-0.27499999999999997 0.31 0"/>
    <axis xyz="0 0 1"/>
  </joint>
  <transmission name="rear_left_wheel_joint_trans">
    <type>transmission_interface/SimpleTransmission</type>
    <actuator name="rear_left_wheel_joint_motor">
      <mechanicalReduction>1</mechanicalReduction>
      <hardwareInterface>hardware_interface/VelocityJointInterface</hardwareInterface>
    </actuator>
    <joint name="rear_left_wheel_joint">
      <hardwareInterface>hardware_interface/VelocityJointInterface</hardwareInterface>
    </joint>
  </transmission>
  <gazebo reference="rear_left_wheel_link">
    <material>Gazebo/Red</material>
  </gazebo>
  <!-- sensors -->
  <!-- Camera -->
  <joint name="front_camera_frame_joint" type="fixed">
    <origin rpy="0 0 0" xyz="0.05 0 0.68"/>
    <parent link="base_pole"/>
    <child link="front_camera_link"/>
  </joint>
  <link name="front_camera_link">
    <inertial>
      <mass value="0.05"/>
      <inertia ixx="0.0" ixy="0.0" ixz="0.0" iyy="0.0" iyz="0.0" izz="0.0"/>
    </inertial>
    <visual>
      <origin rpy="0 0 0" xyz="0 0 0.0"/>
      <geometry>
        <box size="0.0145 0.027 0.027"/>
        <!--
                <mesh filename="package://gazebo_sensor_collection/meshes/econ/see3cam.stl"
                      scale="0.001 0.001 0.001" /> 
                -->
      </geometry>
    </visual>
    <collision>
      <origin rpy="0 0 0" xyz="0 0 0"/>
      <geometry>
        <box size="0.0145 0.027 0.027"/>
      </geometry>
    </collision>
  </link>
  <gazebo reference="front_camera_link">
    <material>Gazebo/FlatBlack</material>
  </gazebo>
  <joint name="front_camera_optical_frame_joint" type="fixed">
    <origin rpy="0 0 0" xyz="0.0 0 0"/>
    <parent link="front_camera_link"/>
    <child link="front_camera_optical_link"/>
  </joint>
  <link name="front_camera_optical_link"/>
  <gazebo reference="front_camera_optical_link">
    <sensor name="front_camera_image_sensor" type="camera">
      <update_rate>15.0</update_rate>
      <camera>
        <horizontal_fov>2.0944</horizontal_fov>
        <image>
          <width>1920</width>
          <height>1080</height>
          <format>R8G8B8</format>
        </image>
        <clip>
          <near>0.02</near>
          <far>200</far>
        </clip>
        <distortion>
          <k1>0.0</k1>
          <k2>0.0</k2>
          <k3>0.0</k3>
          <p1>0.0</p1>
          <p2>0.0</p2>
        </distortion>
      </camera>
      <always_on>1</always_on>
      <visualize>true</visualize>
      <topic>robot_cam</topic>
      <enable_metrics>true</enable_metrics>
      <!-- <plugin name="${name}_controller" filename="libgazebo_ros_camera.so">
                <alwaysOn>true</alwaysOn>
                <updateRate>${hz}</updateRate>
                <cameraName>${name}</cameraName>
                <imageTopicName>image_raw</imageTopicName>
                <cameraInfoTopicName>camera_info</cameraInfoTopicName>
                <frameName>${frame_id}</frameName>
                <autoDistortion>true</autoDistortion>
            </plugin> -->
    </sensor>
  </gazebo>
  <!-- Camera -->
  <joint name="rear_camera_frame_joint" type="fixed">
    <origin rpy="0 0 3.14" xyz="-0.05 0 0.68"/>
    <parent link="base_pole"/>
    <child link="rear_camera_link"/>
  </joint>
  <link name="rear_camera_link">
    <inertial>
      <mass value="0.05"/>
      <inertia ixx="0.0" ixy="0.0" ixz="0.0" iyy="0.0" iyz="0.0" izz="0.0"/>
    </inertial>
    <visual>
      <origin rpy="0 0 0" xyz="0 0 0.0"/>
      <geometry>
        <box size="0.0145 0.027 0.027"/>
        <!--
                <mesh filename="package://gazebo_sensor_collection/meshes/econ/see3cam.stl"
                      scale="0.001 0.001 0.001" /> 
                -->
      </geometry>
    </visual>
    <collision>
      <origin rpy="0 0 0" xyz="0 0 0"/>
      <geometry>
        <box size="0.0145 0.027 0.027"/>
      </geometry>
    </collision>
  </link>
  <gazebo reference="rear_camera_link">
    <material>Gazebo/FlatBlack</material>
  </gazebo>
  <joint name="rear_camera_optical_frame_joint" type="fixed">
    <origin rpy="0 0 0" xyz="0.0 0 0"/>
    <parent link="rear_camera_link"/>
    <child link="rear_camera_optical_link"/>
  </joint>
  <link name="rear_camera_optical_link"/>
  <gazebo reference="rear_camera_optical_link">
    <sensor name="rear_camera_image_sensor" type="camera">
      <update_rate>15.0</update_rate>
      <camera>
        <horizontal_fov>2.0944</horizontal_fov>
        <image>
          <width>1920</width>
          <height>1080</height>
          <format>R8G8B8</format>
        </image>
        <clip>
          <near>0.02</near>
          <far>200</far>
        </clip>
        <distortion>
          <k1>0.0</k1>
          <k2>0.0</k2>
          <k3>0.0</k3>
          <p1>0.0</p1>
          <p2>0.0</p2>
        </distortion>
      </camera>
      <always_on>1</always_on>
      <visualize>true</visualize>
      <topic>robot_cam</topic>
      <enable_metrics>true</enable_metrics>
      <!-- <plugin name="${name}_controller" filename="libgazebo_ros_camera.so">
                <alwaysOn>true</alwaysOn>
                <updateRate>${hz}</updateRate>
                <cameraName>${name}</cameraName>
                <imageTopicName>image_raw</imageTopicName>
                <cameraInfoTopicName>camera_info</cameraInfoTopicName>
                <frameName>${frame_id}</frameName>
                <autoDistortion>true</autoDistortion>
            </plugin> -->
    </sensor>
  </gazebo>
  <!-- Camera -->
  <joint name="left_camera_frame_joint" type="fixed">
    <origin rpy="0 0 1.57" xyz="0 0.05 0.68"/>
    <parent link="base_pole"/>
    <child link="left_camera_link"/>
  </joint>
  <link name="left_camera_link">
    <inertial>
      <mass value="0.05"/>
      <inertia ixx="0.0" ixy="0.0" ixz="0.0" iyy="0.0" iyz="0.0" izz="0.0"/>
    </inertial>
    <visual>
      <origin rpy="0 0 0" xyz="0 0 0.0"/>
      <geometry>
        <box size="0.0145 0.027 0.027"/>
        <!--
                <mesh filename="package://gazebo_sensor_collection/meshes/econ/see3cam.stl"
                      scale="0.001 0.001 0.001" /> 
                -->
      </geometry>
    </visual>
    <collision>
      <origin rpy="0 0 0" xyz="0 0 0"/>
      <geometry>
        <box size="0.0145 0.027 0.027"/>
      </geometry>
    </collision>
  </link>
  <gazebo reference="left_camera_link">
    <material>Gazebo/FlatBlack</material>
  </gazebo>
  <joint name="left_camera_optical_frame_joint" type="fixed">
    <origin rpy="0 0 0" xyz="0.0 0 0"/>
    <parent link="left_camera_link"/>
    <child link="left_camera_optical_link"/>
  </joint>
  <link name="left_camera_optical_link"/>
  <gazebo reference="left_camera_optical_link">
    <sensor name="left_camera_image_sensor" type="camera">
      <update_rate>15.0</update_rate>
      <camera>
        <horizontal_fov>2.0944</horizontal_fov>
        <image>
          <width>1920</width>
          <height>1080</height>
          <format>R8G8B8</format>
        </image>
        <clip>
          <near>0.02</near>
          <far>200</far>
        </clip>
        <distortion>
          <k1>0.0</k1>
          <k2>0.0</k2>
          <k3>0.0</k3>
          <p1>0.0</p1>
          <p2>0.0</p2>
        </distortion>
      </camera>
      <always_on>1</always_on>
      <visualize>true</visualize>
      <topic>robot_cam</topic>
      <enable_metrics>true</enable_metrics>
      <!-- <plugin name="${name}_controller" filename="libgazebo_ros_camera.so">
                <alwaysOn>true</alwaysOn>
                <updateRate>${hz}</updateRate>
                <cameraName>${name}</cameraName>
                <imageTopicName>image_raw</imageTopicName>
                <cameraInfoTopicName>camera_info</cameraInfoTopicName>
                <frameName>${frame_id}</frameName>
                <autoDistortion>true</autoDistortion>
            </plugin> -->
    </sensor>
  </gazebo>
  <!-- Camera -->
  <joint name="right_camera_frame_joint" type="fixed">
    <origin rpy="0 0 -1.57" xyz="0 -0.05 0.68"/>
    <parent link="base_pole"/>
    <child link="right_camera_link"/>
  </joint>
  <link name="right_camera_link">
    <inertial>
      <mass value="0.05"/>
      <inertia ixx="0.0" ixy="0.0" ixz="0.0" iyy="0.0" iyz="0.0" izz="0.0"/>
    </inertial>
    <visual>
      <origin rpy="0 0 0" xyz="0 0 0.0"/>
      <geometry>
        <box size="0.0145 0.027 0.027"/>
        <!--
                <mesh filename="package://gazebo_sensor_collection/meshes/econ/see3cam.stl"
                      scale="0.001 0.001 0.001" /> 
                -->
      </geometry>
    </visual>
    <collision>
      <origin rpy="0 0 0" xyz="0 0 0"/>
      <geometry>
        <box size="0.0145 0.027 0.027"/>
      </geometry>
    </collision>
  </link>
  <gazebo reference="right_camera_link">
    <material>Gazebo/FlatBlack</material>
  </gazebo>
  <joint name="right_camera_optical_frame_joint" type="fixed">
    <origin rpy="0 0 0" xyz="0.0 0 0"/>
    <parent link="right_camera_link"/>
    <child link="right_camera_optical_link"/>
  </joint>
  <link name="right_camera_optical_link"/>
  <gazebo reference="right_camera_optical_link">
    <sensor name="right_camera_image_sensor" type="camera">
      <update_rate>15.0</update_rate>
      <camera>
        <horizontal_fov>2.0944</horizontal_fov>
        <image>
          <width>1920</width>
          <height>1080</height>
          <format>R8G8B8</format>
        </image>
        <clip>
          <near>0.02</near>
          <far>200</far>
        </clip>
        <distortion>
          <k1>0.0</k1>
          <k2>0.0</k2>
          <k3>0.0</k3>
          <p1>0.0</p1>
          <p2>0.0</p2>
        </distortion>
      </camera>
      <always_on>1</always_on>
      <visualize>true</visualize>
      <topic>robot_cam</topic>
      <enable_metrics>true</enable_metrics>
      <!-- <plugin name="${name}_controller" filename="libgazebo_ros_camera.so">
                <alwaysOn>true</alwaysOn>
                <updateRate>${hz}</updateRate>
                <cameraName>${name}</cameraName>
                <imageTopicName>image_raw</imageTopicName>
                <cameraInfoTopicName>camera_info</cameraInfoTopicName>
                <frameName>${frame_id}</frameName>
                <autoDistortion>true</autoDistortion>
            </plugin> -->
    </sensor>
  </gazebo>
  <joint name="pandar_XT32M2X_frame_joint" type="fixed">
    <origin rpy="0 0 0" xyz="0 0 0.74"/>
    <parent link="base_pole"/>
    <child link="pandar_XT32M2X_link"/>
  </joint>
  <link name="pandar_XT32M2X_link">
    <inertial>
      <mass value="0.49"/>
      <origin rpy="0 0 0" xyz="0 0 0.0365"/>
      <inertia ixx="0.000241148" ixy="0" ixz="0" iyy="0.000241148" iyz="0" izz="0.000264"/>
    </inertial>
    <collision name="base_collision">
      <origin rpy="0 0 0" xyz="0 0 0"/>
      <geometry>
        <cylinder length="0.076" radius="0.05"/>
      </geometry>
    </collision>
    <visual name="base_visual">
      <origin rpy="0 0 0" xyz="0 0 0.0"/>
      <geometry>
        <cylinder length="0.076" radius="0.05"/>
      </geometry>
    </visual>
  </link>
  <gazebo reference="pandar_XT32M2X_link">
    <sensor name="lidar" type="gpu_lidar">
      <ignition_frame_id>&quot;pandar_XT32M2X_link&quot;</ignition_frame_id>
      <topic>scan</topic>
      <always_on>true</always_on>
      <visualize>true</visualize>
      <update_rate>20</update_rate>
      <ray>
        <scan>
          <horizontal>
            <samples>1000</samples>
            <resolution>1.000000</resolution>
            <min_angle>-3.141592653589793</min_angle>
            <max_angle>3.141592653589793</max_angle>
          </horizontal>
          <vertical>
            <samples>32</samples>
            <resolution>1</resolution>
            <min_angle>-0.349066</min_angle>
            <max_angle>0.331613</max_angle>
          </vertical>
        </scan>
        <range>
          <min>0.5</min>
          <max>150</max>
          <resolution>0.03</resolution>
        </range>
        <noise>
          <type>gaussian</type>
          <mean>0.0</mean>
          <stddev>0.01</stddev>
        </noise>
      </ray>
    </sensor>
  </gazebo>
  <!-- pose gt
    <gazebo>   
        <plugin name="${namespace}_p3d_plugin" filename="libgazebo_ros_p3d.so">
            <robotNamespace>/</robotNamespace>
            <updateRate>50.0</updateRate>
            <bodyName>base_link</bodyName>
            <topicName>/${namespace}/odom</topicName>
            <gaussianNoise>0.01</gaussianNoise>
            <frameName>world</frameName>
            <xyzOffsets>0 0 0</xyzOffsets>
            <rpyOffsets>0 0 0</rpyOffsets>
        </plugin>
    </gazebo> -->
  <!-- IMU -->
  <link name="imu_link">
    <visual>
      <geometry>
        <box size="0.1 0.1 0.1"/>
      </geometry>
    </visual>
    <collision>
      <geometry>
        <box size="0.1 0.1 0.1"/>
      </geometry>
    </collision>
    <inertial>
      <origin rpy="1.5707963267948966 0 1.5707963267948966" xyz="0 0 0"/>
      <mass value="0.001"/>
      <inertia ixx="1.6666666666666669e-06" ixy="0.0" ixz="0.0" iyy="1.6666666666666669e-06" iyz="0.0" izz="1.6666666666666669e-06"/>
    </inertial>
  </link>
  <gazebo reference="imu_link">
    <sensor name="imu_sensor" type="imu">
      <ignition_frame_id>imu_link</ignition_frame_id>
      <plugin filename="ignition-gazebo-imu-system" name="ignition::gazebo::systems::Imu">
            </plugin>
      <topic>imu</topic>
      <always_on>true</always_on>
      <update_rate>100</update_rate>
      <visualize>true</visualize>
      <imu>
        <angular_velocity>
          <x>
            <noise type="gaussian">
              <mean>0.0</mean>
              <stddev>2e-4</stddev>
              <bias_mean>0.0000075</bias_mean>
              <bias_stddev>0.0000008</bias_stddev>
            </noise>
          </x>
          <y>
            <noise type="gaussian">
              <mean>0.0</mean>
              <stddev>2e-4</stddev>
              <bias_mean>0.0000075</bias_mean>
              <bias_stddev>0.0000008</bias_stddev>
            </noise>
          </y>
          <z>
            <noise type="gaussian">
              <mean>0.0</mean>
              <stddev>2e-4</stddev>
              <bias_mean>0.0000075</bias_mean>
              <bias_stddev>0.0000008</bias_stddev>
            </noise>
          </z>
        </angular_velocity>
        <linear_acceleration>
          <x>
            <noise type="gaussian">
              <mean>0.0</mean>
              <stddev>1.7e-2</stddev>
              <bias_mean>0.1</bias_mean>
              <bias_stddev>0.001</bias_stddev>
            </noise>
          </x>
          <y>
            <noise type="gaussian">
              <mean>0.0</mean>
              <stddev>1.7e-2</stddev>
              <bias_mean>0.1</bias_mean>
              <bias_stddev>0.001</bias_stddev>
            </noise>
          </y>
          <z>
            <noise type="gaussian">
              <mean>0.0</mean>
              <stddev>1.7e-2</stddev>
              <bias_mean>0.1</bias_mean>
              <bias_stddev>0.001</bias_stddev>
            </noise>
          </z>
        </linear_acceleration>
      </imu>
    </sensor>
  </gazebo>
  <joint name="imu_joint" type="fixed">
    <parent link="base_link"/>
    <child link="imu_link"/>
    <origin xyz="0 0 0.01"/>
  </joint>
</robot>
